[2023-09-21T12:43:26.601+0000] {taskinstance.py:1157} INFO - Dependencies all met for dep_context=non-requeueable deps ti=<TaskInstance: master_dag.trigger_cleaning manual__2023-09-21T12:43:20.424527+00:00 [queued]>
[2023-09-21T12:43:26.624+0000] {taskinstance.py:1157} INFO - Dependencies all met for dep_context=requeueable deps ti=<TaskInstance: master_dag.trigger_cleaning manual__2023-09-21T12:43:20.424527+00:00 [queued]>
[2023-09-21T12:43:26.626+0000] {taskinstance.py:1359} INFO - Starting attempt 1 of 1
[2023-09-21T12:43:26.656+0000] {taskinstance.py:1380} INFO - Executing <Task(TriggerDagRunOperator): trigger_cleaning> on 2023-09-21 12:43:20.424527+00:00
[2023-09-21T12:43:26.671+0000] {standard_task_runner.py:57} INFO - Started process 11992 to run task
[2023-09-21T12:43:26.680+0000] {standard_task_runner.py:84} INFO - Running: ['***', 'tasks', 'run', 'master_dag', 'trigger_cleaning', 'manual__2023-09-21T12:43:20.424527+00:00', '--job-id', '66', '--raw', '--subdir', 'DAGS_FOLDER/master_dag.py', '--cfg-path', '/tmp/tmp9zz2o68w']
[2023-09-21T12:43:26.691+0000] {standard_task_runner.py:85} INFO - Job 66: Subtask trigger_cleaning
[2023-09-21T12:43:26.863+0000] {task_command.py:415} INFO - Running <TaskInstance: master_dag.trigger_cleaning manual__2023-09-21T12:43:20.424527+00:00 [running]> on host c14470e00ccc
[2023-09-21T12:43:27.109+0000] {taskinstance.py:1660} INFO - Exporting env vars: AIRFLOW_CTX_DAG_OWNER='***' AIRFLOW_CTX_DAG_ID='master_dag' AIRFLOW_CTX_TASK_ID='trigger_cleaning' AIRFLOW_CTX_EXECUTION_DATE='2023-09-21T12:43:20.424527+00:00' AIRFLOW_CTX_TRY_NUMBER='1' AIRFLOW_CTX_DAG_RUN_ID='manual__2023-09-21T12:43:20.424527+00:00'
[2023-09-21T12:43:27.184+0000] {taskinstance.py:1935} ERROR - Task failed with exception
Traceback (most recent call last):
  File "/home/airflow/.local/lib/python3.8/site-packages/airflow/operators/trigger_dagrun.py", line 163, in execute
    dag_run = trigger_dag(
  File "/home/airflow/.local/lib/python3.8/site-packages/airflow/api/common/trigger_dag.py", line 122, in trigger_dag
    triggers = _trigger_dag(
  File "/home/airflow/.local/lib/python3.8/site-packages/airflow/api/common/trigger_dag.py", line 52, in _trigger_dag
    raise DagNotFound(f"Dag id {dag_id} not found")
airflow.exceptions.DagNotFound: Dag id cleaning_dag not found
[2023-09-21T12:43:27.192+0000] {taskinstance.py:1398} INFO - Marking task as FAILED. dag_id=master_dag, task_id=trigger_cleaning, execution_date=20230921T124320, start_date=20230921T124326, end_date=20230921T124327
[2023-09-21T12:43:27.213+0000] {standard_task_runner.py:104} ERROR - Failed to execute job 66 for task trigger_cleaning (Dag id cleaning_dag not found; 11992)
[2023-09-21T12:43:27.273+0000] {local_task_job_runner.py:228} INFO - Task exited with return code 1
[2023-09-21T12:43:27.352+0000] {taskinstance.py:2776} INFO - 0 downstream tasks scheduled from follow-on schedule check
