[2023-09-21T12:18:43.255+0000] {taskinstance.py:1157} INFO - Dependencies all met for dep_context=non-requeueable deps ti=<TaskInstance: cleaning_dag.cleaning manual__2023-09-21T12:17:49.027136+00:00 [queued]>
[2023-09-21T12:18:43.262+0000] {taskinstance.py:1157} INFO - Dependencies all met for dep_context=requeueable deps ti=<TaskInstance: cleaning_dag.cleaning manual__2023-09-21T12:17:49.027136+00:00 [queued]>
[2023-09-21T12:18:43.263+0000] {taskinstance.py:1359} INFO - Starting attempt 1 of 1
[2023-09-21T12:18:43.364+0000] {taskinstance.py:1380} INFO - Executing <Task(PythonOperator): cleaning> on 2023-09-21 12:17:49.027136+00:00
[2023-09-21T12:18:43.373+0000] {standard_task_runner.py:57} INFO - Started process 10528 to run task
[2023-09-21T12:18:43.380+0000] {standard_task_runner.py:84} INFO - Running: ['***', 'tasks', 'run', 'cleaning_dag', 'cleaning', 'manual__2023-09-21T12:17:49.027136+00:00', '--job-id', '44', '--raw', '--subdir', 'DAGS_FOLDER/cleaning_dag.py', '--cfg-path', '/tmp/tmputt8041j']
[2023-09-21T12:18:43.385+0000] {standard_task_runner.py:85} INFO - Job 44: Subtask cleaning
[2023-09-21T12:18:43.469+0000] {task_command.py:415} INFO - Running <TaskInstance: cleaning_dag.cleaning manual__2023-09-21T12:17:49.027136+00:00 [running]> on host c14470e00ccc
[2023-09-21T12:18:43.592+0000] {taskinstance.py:1660} INFO - Exporting env vars: AIRFLOW_CTX_DAG_OWNER='felicien' AIRFLOW_CTX_DAG_ID='cleaning_dag' AIRFLOW_CTX_TASK_ID='cleaning' AIRFLOW_CTX_EXECUTION_DATE='2023-09-21T12:17:49.027136+00:00' AIRFLOW_CTX_TRY_NUMBER='1' AIRFLOW_CTX_DAG_RUN_ID='manual__2023-09-21T12:17:49.027136+00:00'
[2023-09-21T12:18:43.609+0000] {logging_mixin.py:151} INFO - Raw data shape: (60, 52)
[2023-09-21T12:18:43.654+0000] {logging_mixin.py:151} INFO - Cleaned data shape: (36, 27)
[2023-09-21T12:18:43.658+0000] {taskinstance.py:1935} ERROR - Task failed with exception
Traceback (most recent call last):
  File "/home/airflow/.local/lib/python3.8/site-packages/airflow/operators/python.py", line 192, in execute
    return_value = self.execute_callable()
  File "/home/airflow/.local/lib/python3.8/site-packages/airflow/operators/python.py", line 209, in execute_callable
    return self.python_callable(*self.op_args, **self.op_kwargs)
  File "/opt/airflow/dags/src/cleaning/cleaning.py", line 133, in clean_data
    outlier_clean_df.to_csv(Path.cwd() / "datasets" / "clean" / "clean_data.csv", index=False)
  File "/home/airflow/.local/lib/python3.8/site-packages/pandas/core/generic.py", line 3772, in to_csv
    return DataFrameRenderer(formatter).to_csv(
  File "/home/airflow/.local/lib/python3.8/site-packages/pandas/io/formats/format.py", line 1186, in to_csv
    csv_formatter.save()
  File "/home/airflow/.local/lib/python3.8/site-packages/pandas/io/formats/csvs.py", line 240, in save
    with get_handle(
  File "/home/airflow/.local/lib/python3.8/site-packages/pandas/io/common.py", line 737, in get_handle
    check_parent_directory(str(handle))
  File "/home/airflow/.local/lib/python3.8/site-packages/pandas/io/common.py", line 600, in check_parent_directory
    raise OSError(rf"Cannot save file into a non-existent directory: '{parent}'")
OSError: Cannot save file into a non-existent directory: '/opt/***/datasets/clean'
[2023-09-21T12:18:43.682+0000] {taskinstance.py:1398} INFO - Marking task as FAILED. dag_id=cleaning_dag, task_id=cleaning, execution_date=20230921T121749, start_date=20230921T121843, end_date=20230921T121843
[2023-09-21T12:18:43.698+0000] {standard_task_runner.py:104} ERROR - Failed to execute job 44 for task cleaning (Cannot save file into a non-existent directory: '/opt/***/datasets/clean'; 10528)
[2023-09-21T12:18:43.753+0000] {local_task_job_runner.py:228} INFO - Task exited with return code 1
[2023-09-21T12:18:43.781+0000] {taskinstance.py:2776} INFO - 0 downstream tasks scheduled from follow-on schedule check
