[2023-09-18T12:58:36.890+0000] {taskinstance.py:1157} INFO - Dependencies all met for dep_context=non-requeueable deps ti=<TaskInstance: scraper_dag_v1.get_ids manual__2023-09-18T12:58:35.028297+00:00 [queued]>
[2023-09-18T12:58:36.897+0000] {taskinstance.py:1157} INFO - Dependencies all met for dep_context=requeueable deps ti=<TaskInstance: scraper_dag_v1.get_ids manual__2023-09-18T12:58:35.028297+00:00 [queued]>
[2023-09-18T12:58:36.898+0000] {taskinstance.py:1359} INFO - Starting attempt 1 of 1
[2023-09-18T12:58:36.908+0000] {taskinstance.py:1380} INFO - Executing <Task(PythonOperator): get_ids> on 2023-09-18 12:58:35.028297+00:00
[2023-09-18T12:58:36.915+0000] {standard_task_runner.py:57} INFO - Started process 3188 to run task
[2023-09-18T12:58:36.921+0000] {standard_task_runner.py:84} INFO - Running: ['***', 'tasks', 'run', 'scraper_dag_v1', 'get_ids', 'manual__2023-09-18T12:58:35.028297+00:00', '--job-id', '6', '--raw', '--subdir', 'DAGS_FOLDER/scraper_dag.py', '--cfg-path', '/tmp/tmpxevbyog0']
[2023-09-18T12:58:36.927+0000] {standard_task_runner.py:85} INFO - Job 6: Subtask get_ids
[2023-09-18T12:58:37.001+0000] {task_command.py:415} INFO - Running <TaskInstance: scraper_dag_v1.get_ids manual__2023-09-18T12:58:35.028297+00:00 [running]> on host ae4a9cdd5e86
[2023-09-18T12:58:37.119+0000] {taskinstance.py:1660} INFO - Exporting env vars: AIRFLOW_CTX_DAG_OWNER='felicien' AIRFLOW_CTX_DAG_ID='scraper_dag_v1' AIRFLOW_CTX_TASK_ID='get_ids' AIRFLOW_CTX_EXECUTION_DATE='2023-09-18T12:58:35.028297+00:00' AIRFLOW_CTX_TRY_NUMBER='1' AIRFLOW_CTX_DAG_RUN_ID='manual__2023-09-18T12:58:35.028297+00:00'
[2023-09-18T12:58:38.886+0000] {logging_mixin.py:151} INFO - Number of ids: 60
[2023-09-18T12:58:38.893+0000] {taskinstance.py:1935} ERROR - Task failed with exception
Traceback (most recent call last):
  File "/home/airflow/.local/lib/python3.8/site-packages/airflow/operators/python.py", line 192, in execute
    return_value = self.execute_callable()
  File "/home/airflow/.local/lib/python3.8/site-packages/airflow/operators/python.py", line 209, in execute_callable
    return self.python_callable(*self.op_args, **self.op_kwargs)
  File "/opt/airflow/dags/scraper/id_scraper.py", line 68, in id_scraper
    save_to_txt(ids)
  File "/opt/airflow/dags/scraper/id_scraper.py", line 55, in save_to_txt
    with open(file_path, 'w') as f:
FileNotFoundError: [Errno 2] No such file or directory: '/opt/airflow/data/properties_ids.txt'
[2023-09-18T12:58:38.922+0000] {taskinstance.py:1398} INFO - Marking task as FAILED. dag_id=scraper_dag_v1, task_id=get_ids, execution_date=20230918T125835, start_date=20230918T125836, end_date=20230918T125838
[2023-09-18T12:58:38.938+0000] {standard_task_runner.py:104} ERROR - Failed to execute job 6 for task get_ids ([Errno 2] No such file or directory: '/opt/airflow/data/properties_ids.txt'; 3188)
[2023-09-18T12:58:38.995+0000] {local_task_job_runner.py:228} INFO - Task exited with return code 1
[2023-09-18T12:58:39.026+0000] {taskinstance.py:2776} INFO - 0 downstream tasks scheduled from follow-on schedule check
