[2023-09-21T12:18:43.251+0000] {taskinstance.py:1157} INFO - Dependencies all met for dep_context=non-requeueable deps ti=<TaskInstance: cleaning_dag.cleaning scheduled__2023-09-18T00:00:00+00:00 [queued]>
[2023-09-21T12:18:43.259+0000] {taskinstance.py:1157} INFO - Dependencies all met for dep_context=requeueable deps ti=<TaskInstance: cleaning_dag.cleaning scheduled__2023-09-18T00:00:00+00:00 [queued]>
[2023-09-21T12:18:43.260+0000] {taskinstance.py:1359} INFO - Starting attempt 1 of 1
[2023-09-21T12:18:43.363+0000] {taskinstance.py:1380} INFO - Executing <Task(PythonOperator): cleaning> on 2023-09-18 00:00:00+00:00
[2023-09-21T12:18:43.373+0000] {standard_task_runner.py:57} INFO - Started process 10529 to run task
[2023-09-21T12:18:43.391+0000] {standard_task_runner.py:84} INFO - Running: ['***', 'tasks', 'run', 'cleaning_dag', 'cleaning', 'scheduled__2023-09-18T00:00:00+00:00', '--job-id', '43', '--raw', '--subdir', 'DAGS_FOLDER/cleaning_dag.py', '--cfg-path', '/tmp/tmp8rf1beed']
[2023-09-21T12:18:43.397+0000] {standard_task_runner.py:85} INFO - Job 43: Subtask cleaning
[2023-09-21T12:18:43.498+0000] {task_command.py:415} INFO - Running <TaskInstance: cleaning_dag.cleaning scheduled__2023-09-18T00:00:00+00:00 [running]> on host c14470e00ccc
[2023-09-21T12:18:43.601+0000] {taskinstance.py:1660} INFO - Exporting env vars: AIRFLOW_CTX_DAG_OWNER='felicien' AIRFLOW_CTX_DAG_ID='cleaning_dag' AIRFLOW_CTX_TASK_ID='cleaning' AIRFLOW_CTX_EXECUTION_DATE='2023-09-18T00:00:00+00:00' AIRFLOW_CTX_TRY_NUMBER='1' AIRFLOW_CTX_DAG_RUN_ID='scheduled__2023-09-18T00:00:00+00:00'
[2023-09-21T12:18:43.615+0000] {logging_mixin.py:151} INFO - Raw data shape: (60, 52)
[2023-09-21T12:18:43.654+0000] {logging_mixin.py:151} INFO - Cleaned data shape: (36, 27)
[2023-09-21T12:18:43.658+0000] {taskinstance.py:1935} ERROR - Task failed with exception
Traceback (most recent call last):
  File "/home/airflow/.local/lib/python3.8/site-packages/airflow/operators/python.py", line 192, in execute
    return_value = self.execute_callable()
  File "/home/airflow/.local/lib/python3.8/site-packages/airflow/operators/python.py", line 209, in execute_callable
    return self.python_callable(*self.op_args, **self.op_kwargs)
  File "/opt/airflow/dags/src/cleaning/cleaning.py", line 133, in clean_data
    outlier_clean_df.to_csv(Path.cwd() / "datasets" / "clean" / "clean_data.csv", index=False)
  File "/home/airflow/.local/lib/python3.8/site-packages/pandas/core/generic.py", line 3772, in to_csv
    return DataFrameRenderer(formatter).to_csv(
  File "/home/airflow/.local/lib/python3.8/site-packages/pandas/io/formats/format.py", line 1186, in to_csv
    csv_formatter.save()
  File "/home/airflow/.local/lib/python3.8/site-packages/pandas/io/formats/csvs.py", line 240, in save
    with get_handle(
  File "/home/airflow/.local/lib/python3.8/site-packages/pandas/io/common.py", line 737, in get_handle
    check_parent_directory(str(handle))
  File "/home/airflow/.local/lib/python3.8/site-packages/pandas/io/common.py", line 600, in check_parent_directory
    raise OSError(rf"Cannot save file into a non-existent directory: '{parent}'")
OSError: Cannot save file into a non-existent directory: '/opt/***/datasets/clean'
[2023-09-21T12:18:43.682+0000] {taskinstance.py:1398} INFO - Marking task as FAILED. dag_id=cleaning_dag, task_id=cleaning, execution_date=20230918T000000, start_date=20230921T121843, end_date=20230921T121843
[2023-09-21T12:18:43.698+0000] {standard_task_runner.py:104} ERROR - Failed to execute job 43 for task cleaning (Cannot save file into a non-existent directory: '/opt/***/datasets/clean'; 10529)
[2023-09-21T12:18:43.754+0000] {local_task_job_runner.py:228} INFO - Task exited with return code 1
[2023-09-21T12:18:43.781+0000] {taskinstance.py:2776} INFO - 0 downstream tasks scheduled from follow-on schedule check
[2023-09-21T13:50:10.850+0000] {taskinstance.py:1157} INFO - Dependencies all met for dep_context=non-requeueable deps ti=<TaskInstance: cleaning_dag.cleaning scheduled__2023-09-18T00:00:00+00:00 [queued]>
[2023-09-21T13:50:10.953+0000] {taskinstance.py:1157} INFO - Dependencies all met for dep_context=requeueable deps ti=<TaskInstance: cleaning_dag.cleaning scheduled__2023-09-18T00:00:00+00:00 [queued]>
[2023-09-21T13:50:10.955+0000] {taskinstance.py:1359} INFO - Starting attempt 1 of 1
[2023-09-21T13:50:10.967+0000] {taskinstance.py:1380} INFO - Executing <Task(PythonOperator): cleaning> on 2023-09-18 00:00:00+00:00
[2023-09-21T13:50:10.977+0000] {standard_task_runner.py:57} INFO - Started process 16068 to run task
[2023-09-21T13:50:10.983+0000] {standard_task_runner.py:84} INFO - Running: ['***', 'tasks', 'run', 'cleaning_dag', 'cleaning', 'scheduled__2023-09-18T00:00:00+00:00', '--job-id', '171', '--raw', '--subdir', 'DAGS_FOLDER/cleaning_dag.py', '--cfg-path', '/tmp/tmpb3d4t3ei']
[2023-09-21T13:50:10.990+0000] {standard_task_runner.py:85} INFO - Job 171: Subtask cleaning
[2023-09-21T13:50:11.069+0000] {task_command.py:415} INFO - Running <TaskInstance: cleaning_dag.cleaning scheduled__2023-09-18T00:00:00+00:00 [running]> on host c14470e00ccc
[2023-09-21T13:50:11.158+0000] {taskinstance.py:1660} INFO - Exporting env vars: AIRFLOW_CTX_DAG_OWNER='felicien' AIRFLOW_CTX_DAG_ID='cleaning_dag' AIRFLOW_CTX_TASK_ID='cleaning' AIRFLOW_CTX_EXECUTION_DATE='2023-09-18T00:00:00+00:00' AIRFLOW_CTX_TRY_NUMBER='1' AIRFLOW_CTX_DAG_RUN_ID='scheduled__2023-09-18T00:00:00+00:00'
[2023-09-21T13:50:11.180+0000] {logging_mixin.py:151} INFO - Raw data shape: (60, 52)
[2023-09-21T13:50:11.223+0000] {logging_mixin.py:151} INFO - Cleaned data shape: (30, 27)
[2023-09-21T13:50:11.231+0000] {python.py:194} INFO - Done. Returned value was: None
[2023-09-21T13:50:11.244+0000] {taskinstance.py:1398} INFO - Marking task as SUCCESS. dag_id=cleaning_dag, task_id=cleaning, execution_date=20230918T000000, start_date=20230921T135010, end_date=20230921T135011
[2023-09-21T13:50:11.276+0000] {local_task_job_runner.py:228} INFO - Task exited with return code 0
[2023-09-21T13:50:11.297+0000] {taskinstance.py:2776} INFO - 0 downstream tasks scheduled from follow-on schedule check
