[2023-09-18T13:32:20.794+0000] {taskinstance.py:1157} INFO - Dependencies all met for dep_context=non-requeueable deps ti=<TaskInstance: scraper_dag_v1.get_ids manual__2023-09-18T13:32:19.250469+00:00 [queued]>
[2023-09-18T13:32:20.801+0000] {taskinstance.py:1157} INFO - Dependencies all met for dep_context=requeueable deps ti=<TaskInstance: scraper_dag_v1.get_ids manual__2023-09-18T13:32:19.250469+00:00 [queued]>
[2023-09-18T13:32:20.802+0000] {taskinstance.py:1359} INFO - Starting attempt 1 of 1
[2023-09-18T13:32:20.812+0000] {taskinstance.py:1380} INFO - Executing <Task(PythonOperator): get_ids> on 2023-09-18 13:32:19.250469+00:00
[2023-09-18T13:32:20.818+0000] {standard_task_runner.py:57} INFO - Started process 293 to run task
[2023-09-18T13:32:20.824+0000] {standard_task_runner.py:84} INFO - Running: ['***', 'tasks', 'run', 'scraper_dag_v1', 'get_ids', 'manual__2023-09-18T13:32:19.250469+00:00', '--job-id', '18', '--raw', '--subdir', 'DAGS_FOLDER/scraper_dag.py', '--cfg-path', '/tmp/tmpa4q1wxym']
[2023-09-18T13:32:20.829+0000] {standard_task_runner.py:85} INFO - Job 18: Subtask get_ids
[2023-09-18T13:32:20.904+0000] {task_command.py:415} INFO - Running <TaskInstance: scraper_dag_v1.get_ids manual__2023-09-18T13:32:19.250469+00:00 [running]> on host 53f5a89fc8e9
[2023-09-18T13:32:20.990+0000] {taskinstance.py:1660} INFO - Exporting env vars: AIRFLOW_CTX_DAG_OWNER='felicien' AIRFLOW_CTX_DAG_ID='scraper_dag_v1' AIRFLOW_CTX_TASK_ID='get_ids' AIRFLOW_CTX_EXECUTION_DATE='2023-09-18T13:32:19.250469+00:00' AIRFLOW_CTX_TRY_NUMBER='1' AIRFLOW_CTX_DAG_RUN_ID='manual__2023-09-18T13:32:19.250469+00:00'
[2023-09-18T13:32:22.158+0000] {logging_mixin.py:151} INFO - Number of ids: 60
[2023-09-18T13:32:22.163+0000] {taskinstance.py:1935} ERROR - Task failed with exception
Traceback (most recent call last):
  File "/home/airflow/.local/lib/python3.8/site-packages/airflow/operators/python.py", line 192, in execute
    return_value = self.execute_callable()
  File "/home/airflow/.local/lib/python3.8/site-packages/airflow/operators/python.py", line 209, in execute_callable
    return self.python_callable(*self.op_args, **self.op_kwargs)
  File "/opt/airflow/dags/scraper/id_scraper.py", line 69, in id_scraper
    save_to_txt(ids)
  File "/opt/airflow/dags/scraper/id_scraper.py", line 56, in save_to_txt
    with open(file_path, 'w') as f:
IsADirectoryError: [Errno 21] Is a directory: '/opt/airflow/data/properties_ids_test.txt'
[2023-09-18T13:32:22.180+0000] {taskinstance.py:1398} INFO - Marking task as FAILED. dag_id=scraper_dag_v1, task_id=get_ids, execution_date=20230918T133219, start_date=20230918T133220, end_date=20230918T133222
[2023-09-18T13:32:22.192+0000] {standard_task_runner.py:104} ERROR - Failed to execute job 18 for task get_ids ([Errno 21] Is a directory: '/opt/airflow/data/properties_ids_test.txt'; 293)
[2023-09-18T13:32:22.229+0000] {local_task_job_runner.py:228} INFO - Task exited with return code 1
[2023-09-18T13:32:22.252+0000] {taskinstance.py:2776} INFO - 0 downstream tasks scheduled from follow-on schedule check
