[2023-09-18T13:31:18.314+0000] {taskinstance.py:1157} INFO - Dependencies all met for dep_context=non-requeueable deps ti=<TaskInstance: scraper_dag_v1.get_ids manual__2023-09-18T13:31:15.620748+00:00 [queued]>
[2023-09-18T13:31:18.323+0000] {taskinstance.py:1157} INFO - Dependencies all met for dep_context=requeueable deps ti=<TaskInstance: scraper_dag_v1.get_ids manual__2023-09-18T13:31:15.620748+00:00 [queued]>
[2023-09-18T13:31:18.325+0000] {taskinstance.py:1359} INFO - Starting attempt 1 of 1
[2023-09-18T13:31:18.336+0000] {taskinstance.py:1380} INFO - Executing <Task(PythonOperator): get_ids> on 2023-09-18 13:31:15.620748+00:00
[2023-09-18T13:31:18.344+0000] {standard_task_runner.py:57} INFO - Started process 266 to run task
[2023-09-18T13:31:18.349+0000] {standard_task_runner.py:84} INFO - Running: ['***', 'tasks', 'run', 'scraper_dag_v1', 'get_ids', 'manual__2023-09-18T13:31:15.620748+00:00', '--job-id', '17', '--raw', '--subdir', 'DAGS_FOLDER/scraper_dag.py', '--cfg-path', '/tmp/tmpggs_hqak']
[2023-09-18T13:31:18.354+0000] {standard_task_runner.py:85} INFO - Job 17: Subtask get_ids
[2023-09-18T13:31:18.420+0000] {task_command.py:415} INFO - Running <TaskInstance: scraper_dag_v1.get_ids manual__2023-09-18T13:31:15.620748+00:00 [running]> on host 53f5a89fc8e9
[2023-09-18T13:31:18.526+0000] {taskinstance.py:1660} INFO - Exporting env vars: AIRFLOW_CTX_DAG_OWNER='felicien' AIRFLOW_CTX_DAG_ID='scraper_dag_v1' AIRFLOW_CTX_TASK_ID='get_ids' AIRFLOW_CTX_EXECUTION_DATE='2023-09-18T13:31:15.620748+00:00' AIRFLOW_CTX_TRY_NUMBER='1' AIRFLOW_CTX_DAG_RUN_ID='manual__2023-09-18T13:31:15.620748+00:00'
[2023-09-18T13:31:20.641+0000] {logging_mixin.py:151} INFO - Number of ids: 60
[2023-09-18T13:31:20.648+0000] {taskinstance.py:1935} ERROR - Task failed with exception
Traceback (most recent call last):
  File "/home/airflow/.local/lib/python3.8/site-packages/airflow/operators/python.py", line 192, in execute
    return_value = self.execute_callable()
  File "/home/airflow/.local/lib/python3.8/site-packages/airflow/operators/python.py", line 209, in execute_callable
    return self.python_callable(*self.op_args, **self.op_kwargs)
  File "/opt/airflow/dags/scraper/id_scraper.py", line 70, in id_scraper
    save_to_txt(ids)
  File "/opt/airflow/dags/scraper/id_scraper.py", line 57, in save_to_txt
    with open(file_path, 'w') as f:
IsADirectoryError: [Errno 21] Is a directory: '/opt/airflow/data/properties_ids_test.txt'
[2023-09-18T13:31:20.660+0000] {taskinstance.py:1398} INFO - Marking task as FAILED. dag_id=scraper_dag_v1, task_id=get_ids, execution_date=20230918T133115, start_date=20230918T133118, end_date=20230918T133120
[2023-09-18T13:31:20.671+0000] {standard_task_runner.py:104} ERROR - Failed to execute job 17 for task get_ids ([Errno 21] Is a directory: '/opt/airflow/data/properties_ids_test.txt'; 266)
[2023-09-18T13:31:20.698+0000] {local_task_job_runner.py:228} INFO - Task exited with return code 1
[2023-09-18T13:31:20.717+0000] {taskinstance.py:2776} INFO - 0 downstream tasks scheduled from follow-on schedule check
