[2023-09-21T13:00:24.597+0000] {taskinstance.py:1157} INFO - Dependencies all met for dep_context=non-requeueable deps ti=<TaskInstance: cleaning_dag.wait_for_csv manual__2023-09-21T13:00:22.939626+00:00 [queued]>
[2023-09-21T13:00:24.608+0000] {taskinstance.py:1157} INFO - Dependencies all met for dep_context=requeueable deps ti=<TaskInstance: cleaning_dag.wait_for_csv manual__2023-09-21T13:00:22.939626+00:00 [queued]>
[2023-09-21T13:00:24.609+0000] {taskinstance.py:1359} INFO - Starting attempt 1 of 1
[2023-09-21T13:00:24.624+0000] {taskinstance.py:1380} INFO - Executing <Task(FileSensor): wait_for_csv> on 2023-09-21 13:00:22.939626+00:00
[2023-09-21T13:00:24.630+0000] {standard_task_runner.py:57} INFO - Started process 12952 to run task
[2023-09-21T13:00:24.637+0000] {standard_task_runner.py:84} INFO - Running: ['***', 'tasks', 'run', 'cleaning_dag', 'wait_for_csv', 'manual__2023-09-21T13:00:22.939626+00:00', '--job-id', '85', '--raw', '--subdir', 'DAGS_FOLDER/cleaning_dag.py', '--cfg-path', '/tmp/tmpx60inye_']
[2023-09-21T13:00:24.643+0000] {standard_task_runner.py:85} INFO - Job 85: Subtask wait_for_csv
[2023-09-21T13:00:24.728+0000] {task_command.py:415} INFO - Running <TaskInstance: cleaning_dag.wait_for_csv manual__2023-09-21T13:00:22.939626+00:00 [running]> on host c14470e00ccc
[2023-09-21T13:00:24.850+0000] {taskinstance.py:1660} INFO - Exporting env vars: AIRFLOW_CTX_DAG_OWNER='felicien' AIRFLOW_CTX_DAG_ID='cleaning_dag' AIRFLOW_CTX_TASK_ID='wait_for_csv' AIRFLOW_CTX_EXECUTION_DATE='2023-09-21T13:00:22.939626+00:00' AIRFLOW_CTX_TRY_NUMBER='1' AIRFLOW_CTX_DAG_RUN_ID='manual__2023-09-21T13:00:22.939626+00:00'
[2023-09-21T13:00:24.874+0000] {taskinstance.py:1935} ERROR - Task failed with exception
Traceback (most recent call last):
  File "/home/airflow/.local/lib/python3.8/site-packages/airflow/sensors/base.py", line 257, in execute
    raise e
  File "/home/airflow/.local/lib/python3.8/site-packages/airflow/sensors/base.py", line 239, in execute
    poke_return = self.poke(context)
  File "/home/airflow/.local/lib/python3.8/site-packages/airflow/sensors/filesystem.py", line 61, in poke
    hook = FSHook(self.fs_conn_id)
  File "/home/airflow/.local/lib/python3.8/site-packages/airflow/hooks/filesystem.py", line 38, in __init__
    conn = self.get_connection(conn_id)
  File "/home/airflow/.local/lib/python3.8/site-packages/airflow/hooks/base.py", line 72, in get_connection
    conn = Connection.get_connection_from_secrets(conn_id)
  File "/home/airflow/.local/lib/python3.8/site-packages/airflow/models/connection.py", line 477, in get_connection_from_secrets
    raise AirflowNotFoundException(f"The conn_id `{conn_id}` isn't defined")
airflow.exceptions.AirflowNotFoundException: The conn_id `fs_default` isn't defined
[2023-09-21T13:00:24.878+0000] {taskinstance.py:1398} INFO - Marking task as FAILED. dag_id=cleaning_dag, task_id=wait_for_csv, execution_date=20230921T130022, start_date=20230921T130024, end_date=20230921T130024
[2023-09-21T13:00:24.888+0000] {standard_task_runner.py:104} ERROR - Failed to execute job 85 for task wait_for_csv (The conn_id `fs_default` isn't defined; 12952)
[2023-09-21T13:00:24.932+0000] {local_task_job_runner.py:228} INFO - Task exited with return code 1
[2023-09-21T13:00:24.963+0000] {taskinstance.py:2776} INFO - 0 downstream tasks scheduled from follow-on schedule check
