[2023-09-21T12:59:36.812+0000] {taskinstance.py:1157} INFO - Dependencies all met for dep_context=non-requeueable deps ti=<TaskInstance: cleaning_dag.wait_for_csv manual__2023-09-21T12:49:15.820477+00:00 [queued]>
[2023-09-21T12:59:36.819+0000] {taskinstance.py:1157} INFO - Dependencies all met for dep_context=requeueable deps ti=<TaskInstance: cleaning_dag.wait_for_csv manual__2023-09-21T12:49:15.820477+00:00 [queued]>
[2023-09-21T12:59:36.819+0000] {taskinstance.py:1359} INFO - Starting attempt 1 of 1
[2023-09-21T12:59:36.829+0000] {taskinstance.py:1380} INFO - Executing <Task(FileSensor): wait_for_csv> on 2023-09-21 12:49:15.820477+00:00
[2023-09-21T12:59:36.836+0000] {standard_task_runner.py:57} INFO - Started process 12876 to run task
[2023-09-21T12:59:36.841+0000] {standard_task_runner.py:84} INFO - Running: ['***', 'tasks', 'run', 'cleaning_dag', 'wait_for_csv', 'manual__2023-09-21T12:49:15.820477+00:00', '--job-id', '81', '--raw', '--subdir', 'DAGS_FOLDER/cleaning_dag.py', '--cfg-path', '/tmp/tmpwo2ce_yr']
[2023-09-21T12:59:36.846+0000] {standard_task_runner.py:85} INFO - Job 81: Subtask wait_for_csv
[2023-09-21T12:59:36.912+0000] {task_command.py:415} INFO - Running <TaskInstance: cleaning_dag.wait_for_csv manual__2023-09-21T12:49:15.820477+00:00 [running]> on host c14470e00ccc
[2023-09-21T12:59:37.000+0000] {taskinstance.py:1660} INFO - Exporting env vars: AIRFLOW_CTX_DAG_OWNER='felicien' AIRFLOW_CTX_DAG_ID='cleaning_dag' AIRFLOW_CTX_TASK_ID='wait_for_csv' AIRFLOW_CTX_EXECUTION_DATE='2023-09-21T12:49:15.820477+00:00' AIRFLOW_CTX_TRY_NUMBER='1' AIRFLOW_CTX_DAG_RUN_ID='manual__2023-09-21T12:49:15.820477+00:00'
[2023-09-21T12:59:37.023+0000] {taskinstance.py:1935} ERROR - Task failed with exception
Traceback (most recent call last):
  File "/home/airflow/.local/lib/python3.8/site-packages/airflow/sensors/base.py", line 257, in execute
    raise e
  File "/home/airflow/.local/lib/python3.8/site-packages/airflow/sensors/base.py", line 239, in execute
    poke_return = self.poke(context)
  File "/home/airflow/.local/lib/python3.8/site-packages/airflow/sensors/filesystem.py", line 61, in poke
    hook = FSHook(self.fs_conn_id)
  File "/home/airflow/.local/lib/python3.8/site-packages/airflow/hooks/filesystem.py", line 38, in __init__
    conn = self.get_connection(conn_id)
  File "/home/airflow/.local/lib/python3.8/site-packages/airflow/hooks/base.py", line 72, in get_connection
    conn = Connection.get_connection_from_secrets(conn_id)
  File "/home/airflow/.local/lib/python3.8/site-packages/airflow/models/connection.py", line 477, in get_connection_from_secrets
    raise AirflowNotFoundException(f"The conn_id `{conn_id}` isn't defined")
airflow.exceptions.AirflowNotFoundException: The conn_id `fs_default` isn't defined
[2023-09-21T12:59:37.028+0000] {taskinstance.py:1398} INFO - Marking task as FAILED. dag_id=cleaning_dag, task_id=wait_for_csv, execution_date=20230921T124915, start_date=20230921T125936, end_date=20230921T125937
[2023-09-21T12:59:37.038+0000] {standard_task_runner.py:104} ERROR - Failed to execute job 81 for task wait_for_csv (The conn_id `fs_default` isn't defined; 12876)
[2023-09-21T12:59:37.057+0000] {local_task_job_runner.py:228} INFO - Task exited with return code 1
[2023-09-21T12:59:37.095+0000] {taskinstance.py:2776} INFO - 0 downstream tasks scheduled from follow-on schedule check
