[2023-09-21T12:25:08.308+0000] {taskinstance.py:1157} INFO - Dependencies all met for dep_context=non-requeueable deps ti=<TaskInstance: cleaning_dag.cleaning manual__2023-09-21T12:25:06.962758+00:00 [queued]>
[2023-09-21T12:25:08.315+0000] {taskinstance.py:1157} INFO - Dependencies all met for dep_context=requeueable deps ti=<TaskInstance: cleaning_dag.cleaning manual__2023-09-21T12:25:06.962758+00:00 [queued]>
[2023-09-21T12:25:08.315+0000] {taskinstance.py:1359} INFO - Starting attempt 1 of 1
[2023-09-21T12:25:08.408+0000] {taskinstance.py:1380} INFO - Executing <Task(PythonOperator): cleaning> on 2023-09-21 12:25:06.962758+00:00
[2023-09-21T12:25:08.415+0000] {standard_task_runner.py:57} INFO - Started process 10908 to run task
[2023-09-21T12:25:08.422+0000] {standard_task_runner.py:84} INFO - Running: ['***', 'tasks', 'run', 'cleaning_dag', 'cleaning', 'manual__2023-09-21T12:25:06.962758+00:00', '--job-id', '56', '--raw', '--subdir', 'DAGS_FOLDER/cleaning_dag.py', '--cfg-path', '/tmp/tmpzxahs3jl']
[2023-09-21T12:25:08.427+0000] {standard_task_runner.py:85} INFO - Job 56: Subtask cleaning
[2023-09-21T12:25:08.496+0000] {task_command.py:415} INFO - Running <TaskInstance: cleaning_dag.cleaning manual__2023-09-21T12:25:06.962758+00:00 [running]> on host c14470e00ccc
[2023-09-21T12:25:08.581+0000] {taskinstance.py:1660} INFO - Exporting env vars: AIRFLOW_CTX_DAG_OWNER='felicien' AIRFLOW_CTX_DAG_ID='cleaning_dag' AIRFLOW_CTX_TASK_ID='cleaning' AIRFLOW_CTX_EXECUTION_DATE='2023-09-21T12:25:06.962758+00:00' AIRFLOW_CTX_TRY_NUMBER='1' AIRFLOW_CTX_DAG_RUN_ID='manual__2023-09-21T12:25:06.962758+00:00'
[2023-09-21T12:25:08.587+0000] {taskinstance.py:1935} ERROR - Task failed with exception
Traceback (most recent call last):
  File "/home/airflow/.local/lib/python3.8/site-packages/airflow/operators/python.py", line 192, in execute
    return_value = self.execute_callable()
  File "/home/airflow/.local/lib/python3.8/site-packages/airflow/operators/python.py", line 209, in execute_callable
    return self.python_callable(*self.op_args, **self.op_kwargs)
  File "/opt/airflow/dags/src/cleaning/cleaning.py", line 125, in clean_data
    df = pd.read_csv(read_path)
  File "/home/airflow/.local/lib/python3.8/site-packages/pandas/io/parsers/readers.py", line 912, in read_csv
    return _read(filepath_or_buffer, kwds)
  File "/home/airflow/.local/lib/python3.8/site-packages/pandas/io/parsers/readers.py", line 577, in _read
    parser = TextFileReader(filepath_or_buffer, **kwds)
  File "/home/airflow/.local/lib/python3.8/site-packages/pandas/io/parsers/readers.py", line 1407, in __init__
    self._engine = self._make_engine(f, self.engine)
  File "/home/airflow/.local/lib/python3.8/site-packages/pandas/io/parsers/readers.py", line 1661, in _make_engine
    self.handles = get_handle(
  File "/home/airflow/.local/lib/python3.8/site-packages/pandas/io/common.py", line 859, in get_handle
    handle = open(
FileNotFoundError: [Errno 2] No such file or directory: '/opt/airflow/data/scraped_data.csv'
[2023-09-21T12:25:08.601+0000] {taskinstance.py:1398} INFO - Marking task as FAILED. dag_id=cleaning_dag, task_id=cleaning, execution_date=20230921T122506, start_date=20230921T122508, end_date=20230921T122508
[2023-09-21T12:25:08.611+0000] {standard_task_runner.py:104} ERROR - Failed to execute job 56 for task cleaning ([Errno 2] No such file or directory: '/opt/airflow/data/scraped_data.csv'; 10908)
[2023-09-21T12:25:08.635+0000] {local_task_job_runner.py:228} INFO - Task exited with return code 1
[2023-09-21T12:25:08.655+0000] {taskinstance.py:2776} INFO - 0 downstream tasks scheduled from follow-on schedule check
